[2024-01-30 02:25:38] [WARNING ] discord.client: PyNaCl is not installed, voice will NOT be supported
[2024-01-30 02:25:38] [INFO    ] discord.client: logging in using static token
[2024-01-30 02:26:36] [WARNING ] discord.client: PyNaCl is not installed, voice will NOT be supported
[2024-01-30 02:26:36] [INFO    ] discord.client: logging in using static token
[2024-01-30 02:28:51] [WARNING ] discord.client: PyNaCl is not installed, voice will NOT be supported
[2024-01-30 02:28:51] [INFO    ] discord.client: logging in using static token
[2024-01-30 02:29:52] [WARNING ] discord.client: PyNaCl is not installed, voice will NOT be supported
[2024-01-30 02:29:52] [INFO    ] discord.client: logging in using static token
[2024-01-30 02:31:48] [WARNING ] discord.client: PyNaCl is not installed, voice will NOT be supported
[2024-01-30 02:31:48] [INFO    ] discord.client: logging in using static token
[2024-01-30 02:31:51] [INFO    ] discord.gateway: Shard ID None has connected to Gateway (Session ID: a865b7518ca812219045e9702a52c77e).
[2024-01-30 02:31:53] [ERROR   ] discord.ext.tasks: Unhandled exception in internal background task 'update_contests'.
Traceback (most recent call last):
  File "C:\Users\Lenovo\AppData\Local\Programs\Python\Python311\Lib\zoneinfo\_common.py", line 12, in load_tzdata
    return resources.files(package_name).joinpath(resource_name).open("rb")
           ^^^^^^^^^^^^^^^^^^^^^^^^^^^^^
  File "C:\Users\Lenovo\AppData\Local\Programs\Python\Python311\Lib\importlib\resources\_common.py", line 22, in files
    return from_package(get_package(package))
                        ^^^^^^^^^^^^^^^^^^^^
  File "C:\Users\Lenovo\AppData\Local\Programs\Python\Python311\Lib\importlib\resources\_common.py", line 53, in get_package
    resolved = resolve(package)
               ^^^^^^^^^^^^^^^^
  File "C:\Users\Lenovo\AppData\Local\Programs\Python\Python311\Lib\importlib\resources\_common.py", line 44, in resolve
    return cand if isinstance(cand, types.ModuleType) else importlib.import_module(cand)
                                                           ^^^^^^^^^^^^^^^^^^^^^^^^^^^^^
  File "C:\Users\Lenovo\AppData\Local\Programs\Python\Python311\Lib\importlib\__init__.py", line 126, in import_module
    return _bootstrap._gcd_import(name[level:], package, level)
           ^^^^^^^^^^^^^^^^^^^^^^^^^^^^^^^^^^^^^^^^^^^^^^^^^^^^
  File "<frozen importlib._bootstrap>", line 1204, in _gcd_import
  File "<frozen importlib._bootstrap>", line 1176, in _find_and_load
  File "<frozen importlib._bootstrap>", line 1126, in _find_and_load_unlocked
  File "<frozen importlib._bootstrap>", line 241, in _call_with_frames_removed
  File "<frozen importlib._bootstrap>", line 1204, in _gcd_import
  File "<frozen importlib._bootstrap>", line 1176, in _find_and_load
  File "<frozen importlib._bootstrap>", line 1126, in _find_and_load_unlocked
  File "<frozen importlib._bootstrap>", line 241, in _call_with_frames_removed
  File "<frozen importlib._bootstrap>", line 1204, in _gcd_import
  File "<frozen importlib._bootstrap>", line 1176, in _find_and_load
  File "<frozen importlib._bootstrap>", line 1140, in _find_and_load_unlocked
ModuleNotFoundError: No module named 'tzdata'

During handling of the above exception, another exception occurred:

Traceback (most recent call last):
  File "C:\PycharmProjects\venvs\IEEECS-bot\Lib\site-packages\discord\ext\tasks\__init__.py", line 239, in _loop
    await self.coro(*args, **kwargs)
  File "C:\PycharmProjects\IEEECS-bot\Cogs\contests.py", line 24, in update_contests
    now: datetime.datetime = datetime.datetime.now(ZoneInfo("Asia/Kolkata"))
                                                   ^^^^^^^^^^^^^^^^^^^^^^^^
  File "C:\Users\Lenovo\AppData\Local\Programs\Python\Python311\Lib\zoneinfo\_common.py", line 24, in load_tzdata
    raise ZoneInfoNotFoundError(f"No time zone found with key {key}")
zoneinfo._common.ZoneInfoNotFoundError: 'No time zone found with key Asia/Kolkata'
[2024-01-30 02:31:53] [ERROR   ] discord.ext.tasks: Unhandled exception in internal background task 'send_news'.
Traceback (most recent call last):
  File "C:\Users\Lenovo\AppData\Local\Programs\Python\Python311\Lib\zoneinfo\_common.py", line 12, in load_tzdata
    return resources.files(package_name).joinpath(resource_name).open("rb")
           ^^^^^^^^^^^^^^^^^^^^^^^^^^^^^
  File "C:\Users\Lenovo\AppData\Local\Programs\Python\Python311\Lib\importlib\resources\_common.py", line 22, in files
    return from_package(get_package(package))
                        ^^^^^^^^^^^^^^^^^^^^
  File "C:\Users\Lenovo\AppData\Local\Programs\Python\Python311\Lib\importlib\resources\_common.py", line 53, in get_package
    resolved = resolve(package)
               ^^^^^^^^^^^^^^^^
  File "C:\Users\Lenovo\AppData\Local\Programs\Python\Python311\Lib\importlib\resources\_common.py", line 44, in resolve
    return cand if isinstance(cand, types.ModuleType) else importlib.import_module(cand)
                                                           ^^^^^^^^^^^^^^^^^^^^^^^^^^^^^
  File "C:\Users\Lenovo\AppData\Local\Programs\Python\Python311\Lib\importlib\__init__.py", line 126, in import_module
    return _bootstrap._gcd_import(name[level:], package, level)
           ^^^^^^^^^^^^^^^^^^^^^^^^^^^^^^^^^^^^^^^^^^^^^^^^^^^^
  File "<frozen importlib._bootstrap>", line 1204, in _gcd_import
  File "<frozen importlib._bootstrap>", line 1176, in _find_and_load
  File "<frozen importlib._bootstrap>", line 1126, in _find_and_load_unlocked
  File "<frozen importlib._bootstrap>", line 241, in _call_with_frames_removed
  File "<frozen importlib._bootstrap>", line 1204, in _gcd_import
  File "<frozen importlib._bootstrap>", line 1176, in _find_and_load
  File "<frozen importlib._bootstrap>", line 1126, in _find_and_load_unlocked
  File "<frozen importlib._bootstrap>", line 241, in _call_with_frames_removed
  File "<frozen importlib._bootstrap>", line 1204, in _gcd_import
  File "<frozen importlib._bootstrap>", line 1176, in _find_and_load
  File "<frozen importlib._bootstrap>", line 1140, in _find_and_load_unlocked
ModuleNotFoundError: No module named 'tzdata'

During handling of the above exception, another exception occurred:

Traceback (most recent call last):
  File "C:\PycharmProjects\venvs\IEEECS-bot\Lib\site-packages\discord\ext\tasks\__init__.py", line 239, in _loop
    await self.coro(*args, **kwargs)
  File "C:\PycharmProjects\IEEECS-bot\Cogs\news.py", line 33, in send_news
    now: datetime.datetime = datetime.datetime.now(ZoneInfo("Asia/Kolkata"))
                                                   ^^^^^^^^^^^^^^^^^^^^^^^^
  File "C:\Users\Lenovo\AppData\Local\Programs\Python\Python311\Lib\zoneinfo\_common.py", line 24, in load_tzdata
    raise ZoneInfoNotFoundError(f"No time zone found with key {key}")
zoneinfo._common.ZoneInfoNotFoundError: 'No time zone found with key Asia/Kolkata'
[2024-01-30 02:31:53] [ERROR   ] discord.ext.tasks: Unhandled exception in internal background task 'send_questions'.
Traceback (most recent call last):
  File "C:\Users\Lenovo\AppData\Local\Programs\Python\Python311\Lib\zoneinfo\_common.py", line 12, in load_tzdata
    return resources.files(package_name).joinpath(resource_name).open("rb")
           ^^^^^^^^^^^^^^^^^^^^^^^^^^^^^
  File "C:\Users\Lenovo\AppData\Local\Programs\Python\Python311\Lib\importlib\resources\_common.py", line 22, in files
    return from_package(get_package(package))
                        ^^^^^^^^^^^^^^^^^^^^
  File "C:\Users\Lenovo\AppData\Local\Programs\Python\Python311\Lib\importlib\resources\_common.py", line 53, in get_package
    resolved = resolve(package)
               ^^^^^^^^^^^^^^^^
  File "C:\Users\Lenovo\AppData\Local\Programs\Python\Python311\Lib\importlib\resources\_common.py", line 44, in resolve
    return cand if isinstance(cand, types.ModuleType) else importlib.import_module(cand)
                                                           ^^^^^^^^^^^^^^^^^^^^^^^^^^^^^
  File "C:\Users\Lenovo\AppData\Local\Programs\Python\Python311\Lib\importlib\__init__.py", line 126, in import_module
    return _bootstrap._gcd_import(name[level:], package, level)
           ^^^^^^^^^^^^^^^^^^^^^^^^^^^^^^^^^^^^^^^^^^^^^^^^^^^^
  File "<frozen importlib._bootstrap>", line 1204, in _gcd_import
  File "<frozen importlib._bootstrap>", line 1176, in _find_and_load
  File "<frozen importlib._bootstrap>", line 1126, in _find_and_load_unlocked
  File "<frozen importlib._bootstrap>", line 241, in _call_with_frames_removed
  File "<frozen importlib._bootstrap>", line 1204, in _gcd_import
  File "<frozen importlib._bootstrap>", line 1176, in _find_and_load
  File "<frozen importlib._bootstrap>", line 1126, in _find_and_load_unlocked
  File "<frozen importlib._bootstrap>", line 241, in _call_with_frames_removed
  File "<frozen importlib._bootstrap>", line 1204, in _gcd_import
  File "<frozen importlib._bootstrap>", line 1176, in _find_and_load
  File "<frozen importlib._bootstrap>", line 1140, in _find_and_load_unlocked
ModuleNotFoundError: No module named 'tzdata'

During handling of the above exception, another exception occurred:

Traceback (most recent call last):
  File "C:\PycharmProjects\venvs\IEEECS-bot\Lib\site-packages\discord\ext\tasks\__init__.py", line 239, in _loop
    await self.coro(*args, **kwargs)
  File "C:\PycharmProjects\IEEECS-bot\Cogs\questions.py", line 672, in send_questions
    now: datetime.datetime = datetime.datetime.now(ZoneInfo("Asia/Kolkata"))
                                                   ^^^^^^^^^^^^^^^^^^^^^^^^
  File "C:\Users\Lenovo\AppData\Local\Programs\Python\Python311\Lib\zoneinfo\_common.py", line 24, in load_tzdata
    raise ZoneInfoNotFoundError(f"No time zone found with key {key}")
zoneinfo._common.ZoneInfoNotFoundError: 'No time zone found with key Asia/Kolkata'
[2024-01-30 02:31:53] [ERROR   ] discord.ext.tasks: Unhandled exception in internal background task 'send_reddits'.
Traceback (most recent call last):
  File "C:\Users\Lenovo\AppData\Local\Programs\Python\Python311\Lib\zoneinfo\_common.py", line 12, in load_tzdata
    return resources.files(package_name).joinpath(resource_name).open("rb")
           ^^^^^^^^^^^^^^^^^^^^^^^^^^^^^
  File "C:\Users\Lenovo\AppData\Local\Programs\Python\Python311\Lib\importlib\resources\_common.py", line 22, in files
    return from_package(get_package(package))
                        ^^^^^^^^^^^^^^^^^^^^
  File "C:\Users\Lenovo\AppData\Local\Programs\Python\Python311\Lib\importlib\resources\_common.py", line 53, in get_package
    resolved = resolve(package)
               ^^^^^^^^^^^^^^^^
  File "C:\Users\Lenovo\AppData\Local\Programs\Python\Python311\Lib\importlib\resources\_common.py", line 44, in resolve
    return cand if isinstance(cand, types.ModuleType) else importlib.import_module(cand)
                                                           ^^^^^^^^^^^^^^^^^^^^^^^^^^^^^
  File "C:\Users\Lenovo\AppData\Local\Programs\Python\Python311\Lib\importlib\__init__.py", line 126, in import_module
    return _bootstrap._gcd_import(name[level:], package, level)
           ^^^^^^^^^^^^^^^^^^^^^^^^^^^^^^^^^^^^^^^^^^^^^^^^^^^^
  File "<frozen importlib._bootstrap>", line 1204, in _gcd_import
  File "<frozen importlib._bootstrap>", line 1176, in _find_and_load
  File "<frozen importlib._bootstrap>", line 1126, in _find_and_load_unlocked
  File "<frozen importlib._bootstrap>", line 241, in _call_with_frames_removed
  File "<frozen importlib._bootstrap>", line 1204, in _gcd_import
  File "<frozen importlib._bootstrap>", line 1176, in _find_and_load
  File "<frozen importlib._bootstrap>", line 1126, in _find_and_load_unlocked
  File "<frozen importlib._bootstrap>", line 241, in _call_with_frames_removed
  File "<frozen importlib._bootstrap>", line 1204, in _gcd_import
  File "<frozen importlib._bootstrap>", line 1176, in _find_and_load
  File "<frozen importlib._bootstrap>", line 1140, in _find_and_load_unlocked
ModuleNotFoundError: No module named 'tzdata'

During handling of the above exception, another exception occurred:

Traceback (most recent call last):
  File "C:\PycharmProjects\venvs\IEEECS-bot\Lib\site-packages\discord\ext\tasks\__init__.py", line 239, in _loop
    await self.coro(*args, **kwargs)
  File "C:\PycharmProjects\IEEECS-bot\Cogs\reddit.py", line 81, in send_reddits
    now: datetime.datetime = datetime.datetime.now(ZoneInfo("Asia/Kolkata"))
                                                   ^^^^^^^^^^^^^^^^^^^^^^^^
  File "C:\Users\Lenovo\AppData\Local\Programs\Python\Python311\Lib\zoneinfo\_common.py", line 24, in load_tzdata
    raise ZoneInfoNotFoundError(f"No time zone found with key {key}")
zoneinfo._common.ZoneInfoNotFoundError: 'No time zone found with key Asia/Kolkata'
[2024-01-30 02:33:09] [WARNING ] discord.client: PyNaCl is not installed, voice will NOT be supported
[2024-01-30 02:33:09] [INFO    ] discord.client: logging in using static token
[2024-01-30 02:33:12] [INFO    ] discord.gateway: Shard ID None has connected to Gateway (Session ID: a0f8371bbf450281f372668d989332c1).
